<?xml version="1.0" encoding="UTF-8"?>
<!-- =================================================================================== -->
<!-- |    This document was autogenerated by xacro4sdf from ../models/dot_control.sdf.xmacro | -->
<!-- |    EDITING THIS FILE BY HAND IS NOT RECOMMENDED                                 | -->
<!-- =================================================================================== -->
<sdf version="1.7">
	<!-- Robot dimensions, all units meters.
        FORWARD IS +X
        LEFT IS +Y
        UP IS +Z -->
	<!-- Hip abduction axis forward/back from robot origin -->
	<!-- Hip abduction axis y displacement -->
	<!-- Hip abduction axis to hip axis -->
	<!-- Knee info -->
	<model name="dot">
		<link name="body">
			<inertial>
				<pose>0 0 0 0 0 0</pose>
				<mass>2.0</mass>
				<inertia>
					<ixx>0.0020833333333333337</ixx>
					<ixy>0</ixy>
					<ixz>0</ixz>
					<iyy>0.015416666666666667</iyy>
					<iyz>0</iyz>
					<izz>0.016666666666666666</izz>
				</inertia>
			</inertial>
			<visual name="body_visual">
				<geometry>
					<box>
						<size>0.3 0.1 0.05</size>
					</box>
				</geometry>
				<material>
					<ambient>1. 0.8 0.6 1.0</ambient>
					<diffuse>1. 0.8 0.6 1.0</diffuse>
				</material>
			</visual>
			<collision name="body_collision">
				<geometry>
					<box>
						<size>0.3 0.1 0.05</size>
					</box>
				</geometry>
			</collision>
		</link>
		<!-- Pelvis -->
		<link name="left_front_pelvis">
			<pose relative_to="body">
                0.125 0 0 0 0 0
            </pose>
			<inertial>
				<pose>0 0 0 0 0 0</pose>
				<mass>0.0001</mass>
				<inertia>
					<ixx>3.3333333333333335e-11</ixx>
					<ixy>0</ixy>
					<ixz>0</ixz>
					<iyy>3.3333333333333335e-11</iyy>
					<iyz>0</iyz>
					<izz>5.000000000000001e-11</izz>
				</inertia>
			</inertial>
			<visual name="left_front_pelvis_rod_visual">
				<!-- Cylinders are along +z -->
				<pose> 0 0.025 0 1.57075 0 0 </pose>
				<geometry>
					<cylinder>
						<radius>0.005</radius>
						<length>0.05</length>
					</cylinder>
				</geometry>
				<material>
					<ambient>1. 0.5 0.25 1.</ambient>
					<diffuse>1. 0.5 0.25 1.</diffuse>
				</material>
			</visual>
			<visual name="left_front_pelvis_ball_visual">
				<pose>0 0.05 0 0 0 0 </pose>
				<geometry>
					<sphere>
						<radius>0.01</radius>
					</sphere>
				</geometry>
				<material>
					<ambient>1. 0.5 0.25 1.</ambient>
					<diffuse>1. 0.5 0.25 1.</diffuse>
				</material>
			</visual>
		</link>
		<joint name="left_front_body2pelvis" type="fixed">
			<parent>body</parent>
			<child>left_front_pelvis</child>
			<pose relative_to="body">
                0.125 0 0 0 0 0
            </pose>
		</joint>
		<!-- hip abduction-->
		<link name="left_front_hip_inner">
			<pose relative_to="left_front_pelvis">
                0 0.05 0 0 0 0
            </pose>
			<inertial>
				<!-- Guessing the massive servos pull the COM to right between them -->
				<pose>-0.01 0.01 0 0 0 0</pose>
				<!-- approx standin inertia -->
				<mass>0.1</mass>
				<inertia>
					<ixx>9.895833333333333e-07</ixx>
					<ixy>0</ixy>
					<ixz>0</ixz>
					<iyy>9.895833333333333e-07</iyy>
					<iyz>0</iyz>
					<izz>3.125e-07</izz>
				</inertia>
				<mass>0.1</mass>
			</inertial>
			<visual name="left_front_inner_hip_rod_x_visual">
				<!-- Cylinders are along +z -->
				<pose> 0.01/2 0 0 0 1.57075 0 </pose>
				<geometry>
					<cylinder>
						<radius>0.0025</radius>
						<length>0.01</length>
					</cylinder>
				</geometry>
				<material>
					<ambient>1. 0.5 0.25 1.</ambient>
					<diffuse>1. 0.5 0.25 1.</diffuse>
				</material>
			</visual>
			<visual name="left_front_inner_hip_rod_y_visual">
				<!-- Cylinders are along +z -->
				<pose> 0.01 0.005 0 1.57075 0 0 </pose>
				<geometry>
					<cylinder>
						<radius>0.0025</radius>
						<length>0.01</length>
					</cylinder>
				</geometry>
				<material>
					<ambient>1. 0.5 0.25 1.</ambient>
					<diffuse>1. 0.5 0.25 1.</diffuse>
				</material>
			</visual>
			<visual name="left_front_inner_hip_ball_visual">
				<pose>0.01 0.01 0 0 0 0 </pose>
				<geometry>
					<sphere>
						<radius>0.01</radius>
					</sphere>
				</geometry>
				<material>
					<ambient>1. 0.5 0.25 1.</ambient>
					<diffuse>1. 0.5 0.25 1.</diffuse>
				</material>
			</visual>
			<visual name="left_front_inner_hip_box_visual">
				<pose>0.005 0.005 0 0 0 0</pose>
				<geometry>
					<box>
						<size>0.04 0.04 0.04</size>
					</box>
				</geometry>
				<material>
					<ambient>1. 0.5 0.25 1.</ambient>
					<diffuse>1. 0.5 0.25 1.</diffuse>
				</material>
			</visual>
		</link>
		<joint name="left_front_hip_roll" type="revolute">
			<parent>left_front_pelvis</parent>
			<child>left_front_hip_inner</child>
			<pose relative_to="left_front_pelvis">
                0 0.05 0. 0. 0. 0
            </pose>
			<axis>
				<xyz>1. 0. 0.</xyz>
				<limit>
					<lower>-1.57075</lower>
					<upper>1.57075</upper>
					<effort>1.0</effort>
					<velocity>10</velocity>
				</limit>
				<dynamics>
					<damping>1.5e-2</damping>
				</dynamics>
			</axis>
		</joint>
		<!-- hip-->
		<link name="left_front_hip">
			<!-- Goes straight down at base posture -->
			<pose relative_to="left_front_hip_inner">
                0.01 0.01 0 0 0 0
            </pose>
			<inertial>
				<pose>0 0 -0.055 0 0 0</pose>
				<mass>0.05</mass>
				<inertia>
					<ixx>5.049479166666667e-05</ixx>
					<ixy>0</ixy>
					<ixz>0</ixz>
					<iyy>5.049479166666667e-05</iyy>
					<iyz>0</iyz>
					<izz>1.5625e-07</izz>
				</inertia>
			</inertial>
			<visual name="left_front_hip_rod_visual">
				<!-- Cylinders are along +z -->
				<pose> 0 0 -0.055 0 0 0 </pose>
				<geometry>
					<cylinder>
						<radius>0.0025</radius>
						<length>0.11</length>
					</cylinder>
				</geometry>
				<material>
					<ambient>1. 0.5 0.25 1.</ambient>
					<diffuse>1. 0.5 0.25 1.</diffuse>
				</material>
			</visual>
			<visual name="left_front_hip_ball_vis">
				<pose>0 0 -0.11 0. 0. 0.</pose>
				<geometry>
					<sphere>
						<radius>0.01</radius>
					</sphere>
				</geometry>
				<material>
					<ambient>1. 0.5 0.25 1.</ambient>
					<diffuse>1. 0.5 0.25 1.</diffuse>
				</material>
			</visual>
			<collision name="left_front_hip_ball_vis">
				<pose>0 0 -0.11 0. 0. 0.</pose>
				<geometry>
					<sphere>
						<radius>0.01</radius>
					</sphere>
				</geometry>
			</collision>
		</link>
		<joint name="left_front_hip_pitch" type="revolute">
			<parent>left_front_hip_inner</parent>
			<child>left_front_hip</child>
			<pose relative_to="left_front_hip_inner">
                0.01 0.01 0 0 0 0
            </pose>
			<axis>
				<xyz>0. 1. 0.</xyz>
				<limit>
					<lower>-1.57075</lower>
					<upper>1.57075</upper>
					<effort>1.0</effort>
					<velocity>10</velocity>
				</limit>
				<dynamics>
					<damping>1.5e-2</damping>
				</dynamics>
			</axis>
		</joint>
		<!-- shin-->
		<link name="left_front_shin">
			<!-- Points straight down at angle=0 -->
			<pose relative_to="left_front_hip">
                0 0.01 -0.11 0 0 0
            </pose>
			<inertial>
				<pose>0 0 -0.055 0 0 0</pose>
				<mass>0.05</mass>
				<inertia>
					<ixx>5.049479166666667e-05</ixx>
					<ixy>0</ixy>
					<ixz>0</ixz>
					<iyy>5.049479166666667e-05</iyy>
					<iyz>0</iyz>
					<izz>1.5625e-07</izz>
				</inertia>
			</inertial>
			<visual name="left_front_hip_rod_visual">
				<!-- Cylinders are along +z -->
				<pose> 0 0 -0.055 0 0 0 </pose>
				<geometry>
					<cylinder>
						<radius>0.0025</radius>
						<length>0.11</length>
					</cylinder>
				</geometry>
				<material>
					<ambient>1. 0.5 0.25 1.</ambient>
					<diffuse>1. 0.5 0.25 1.</diffuse>
				</material>
			</visual>
			<visual name="left_front_shin_ball_vis">
				<pose>0 0 -0.11 0. 0. 0.</pose>
				<geometry>
					<sphere>
						<radius>0.01</radius>
					</sphere>
				</geometry>
				<material>
					<ambient>1. 0.5 0.25 1.</ambient>
					<diffuse>1. 0.5 0.25 1.</diffuse>
				</material>
			</visual>
			<collision name="left_front_shin_ball_vis">
				<pose>0 0 -0.11 0. 0. 0.</pose>
				<geometry>
					<sphere>
						<radius>0.01</radius>
					</sphere>
				</geometry>
			</collision>
		</link>
		<joint name="left_front_knee_pitch" type="revolute">
			<parent>left_front_hip</parent>
			<child>left_front_shin</child>
			<pose relative_to="left_front_hip">
                0 0.01 -0.11 0 0 0
            </pose>
			<axis>
				<!-- axis is in child frame -->
				<xyz>0 1. 0</xyz>
				<limit>
					<lower>-3.1415</lower>
					<upper>0</upper>
					<effort>1.0</effort>
					<velocity>10</velocity>
				</limit>
				<dynamics>
					<damping>1.5e-2</damping>
				</dynamics>
				<initial_position>-1.57075</initial_position>
			</axis>
		</joint>
		<!-- Pelvis -->
		<link name="right_front_pelvis">
			<pose relative_to="body">
                0.125 0 0 0 0 0
            </pose>
			<inertial>
				<pose>0 0 0 0 0 0</pose>
				<mass>0.0001</mass>
				<inertia>
					<ixx>3.3333333333333335e-11</ixx>
					<ixy>0</ixy>
					<ixz>0</ixz>
					<iyy>3.3333333333333335e-11</iyy>
					<iyz>0</iyz>
					<izz>5.000000000000001e-11</izz>
				</inertia>
			</inertial>
			<visual name="right_front_pelvis_rod_visual">
				<!-- Cylinders are along +z -->
				<pose> 0 -0.025 0 1.57075 0 0 </pose>
				<geometry>
					<cylinder>
						<radius>0.005</radius>
						<length>0.05</length>
					</cylinder>
				</geometry>
				<material>
					<ambient>1. 0.25 0.5 1.</ambient>
					<diffuse>1. 0.25 0.5 1.</diffuse>
				</material>
			</visual>
			<visual name="right_front_pelvis_ball_visual">
				<pose>0 -0.05 0 0 0 0 </pose>
				<geometry>
					<sphere>
						<radius>0.01</radius>
					</sphere>
				</geometry>
				<material>
					<ambient>1. 0.25 0.5 1.</ambient>
					<diffuse>1. 0.25 0.5 1.</diffuse>
				</material>
			</visual>
		</link>
		<joint name="right_front_body2pelvis" type="fixed">
			<parent>body</parent>
			<child>right_front_pelvis</child>
			<pose relative_to="body">
                0.125 0 0 0 0 0
            </pose>
		</joint>
		<!-- hip abduction-->
		<link name="right_front_hip_inner">
			<pose relative_to="right_front_pelvis">
                0 -0.05 0 0 0 0
            </pose>
			<inertial>
				<!-- Guessing the massive servos pull the COM to right between them -->
				<pose>-0.01 -0.01 0 0 0 0</pose>
				<!-- approx standin inertia -->
				<mass>0.1</mass>
				<inertia>
					<ixx>9.895833333333333e-07</ixx>
					<ixy>0</ixy>
					<ixz>0</ixz>
					<iyy>9.895833333333333e-07</iyy>
					<iyz>0</iyz>
					<izz>3.125e-07</izz>
				</inertia>
				<mass>0.1</mass>
			</inertial>
			<visual name="right_front_inner_hip_rod_x_visual">
				<!-- Cylinders are along +z -->
				<pose> 0.01/2 0 0 0 1.57075 0 </pose>
				<geometry>
					<cylinder>
						<radius>0.0025</radius>
						<length>0.01</length>
					</cylinder>
				</geometry>
				<material>
					<ambient>1. 0.25 0.5 1.</ambient>
					<diffuse>1. 0.25 0.5 1.</diffuse>
				</material>
			</visual>
			<visual name="right_front_inner_hip_rod_y_visual">
				<!-- Cylinders are along +z -->
				<pose> 0.01 -0.005 0 1.57075 0 0 </pose>
				<geometry>
					<cylinder>
						<radius>0.0025</radius>
						<length>0.01</length>
					</cylinder>
				</geometry>
				<material>
					<ambient>1. 0.25 0.5 1.</ambient>
					<diffuse>1. 0.25 0.5 1.</diffuse>
				</material>
			</visual>
			<visual name="right_front_inner_hip_ball_visual">
				<pose>0.01 -0.01 0 0 0 0 </pose>
				<geometry>
					<sphere>
						<radius>0.01</radius>
					</sphere>
				</geometry>
				<material>
					<ambient>1. 0.25 0.5 1.</ambient>
					<diffuse>1. 0.25 0.5 1.</diffuse>
				</material>
			</visual>
			<visual name="right_front_inner_hip_box_visual">
				<pose>0.005 -0.005 0 0 0 0</pose>
				<geometry>
					<box>
						<size>0.04 0.04 0.04</size>
					</box>
				</geometry>
				<material>
					<ambient>1. 0.25 0.5 1.</ambient>
					<diffuse>1. 0.25 0.5 1.</diffuse>
				</material>
			</visual>
		</link>
		<joint name="right_front_hip_roll" type="revolute">
			<parent>right_front_pelvis</parent>
			<child>right_front_hip_inner</child>
			<pose relative_to="right_front_pelvis">
                0 -0.05 0. 0. 0. 0
            </pose>
			<axis>
				<xyz>1. 0. 0.</xyz>
				<limit>
					<lower>-1.57075</lower>
					<upper>1.57075</upper>
					<effort>1.0</effort>
					<velocity>10</velocity>
				</limit>
				<dynamics>
					<damping>1.5e-2</damping>
				</dynamics>
			</axis>
		</joint>
		<!-- hip-->
		<link name="right_front_hip">
			<!-- Goes straight down at base posture -->
			<pose relative_to="right_front_hip_inner">
                0.01 -0.01 0 0 0 0
            </pose>
			<inertial>
				<pose>0 0 -0.055 0 0 0</pose>
				<mass>0.05</mass>
				<inertia>
					<ixx>5.049479166666667e-05</ixx>
					<ixy>0</ixy>
					<ixz>0</ixz>
					<iyy>5.049479166666667e-05</iyy>
					<iyz>0</iyz>
					<izz>1.5625e-07</izz>
				</inertia>
			</inertial>
			<visual name="right_front_hip_rod_visual">
				<!-- Cylinders are along +z -->
				<pose> 0 0 -0.055 0 0 0 </pose>
				<geometry>
					<cylinder>
						<radius>0.0025</radius>
						<length>0.11</length>
					</cylinder>
				</geometry>
				<material>
					<ambient>1. 0.25 0.5 1.</ambient>
					<diffuse>1. 0.25 0.5 1.</diffuse>
				</material>
			</visual>
			<visual name="right_front_hip_ball_vis">
				<pose>0 0 -0.11 0. 0. 0.</pose>
				<geometry>
					<sphere>
						<radius>0.01</radius>
					</sphere>
				</geometry>
				<material>
					<ambient>1. 0.25 0.5 1.</ambient>
					<diffuse>1. 0.25 0.5 1.</diffuse>
				</material>
			</visual>
			<collision name="right_front_hip_ball_vis">
				<pose>0 0 -0.11 0. 0. 0.</pose>
				<geometry>
					<sphere>
						<radius>0.01</radius>
					</sphere>
				</geometry>
			</collision>
		</link>
		<joint name="right_front_hip_pitch" type="revolute">
			<parent>right_front_hip_inner</parent>
			<child>right_front_hip</child>
			<pose relative_to="right_front_hip_inner">
                0.01 -0.01 0 0 0 0
            </pose>
			<axis>
				<xyz>0. 1. 0.</xyz>
				<limit>
					<lower>-1.57075</lower>
					<upper>1.57075</upper>
					<effort>1.0</effort>
					<velocity>10</velocity>
				</limit>
				<dynamics>
					<damping>1.5e-2</damping>
				</dynamics>
			</axis>
		</joint>
		<!-- shin-->
		<link name="right_front_shin">
			<!-- Points straight down at angle=0 -->
			<pose relative_to="right_front_hip">
                0 -0.01 -0.11 0 0 0
            </pose>
			<inertial>
				<pose>0 0 -0.055 0 0 0</pose>
				<mass>0.05</mass>
				<inertia>
					<ixx>5.049479166666667e-05</ixx>
					<ixy>0</ixy>
					<ixz>0</ixz>
					<iyy>5.049479166666667e-05</iyy>
					<iyz>0</iyz>
					<izz>1.5625e-07</izz>
				</inertia>
			</inertial>
			<visual name="right_front_hip_rod_visual">
				<!-- Cylinders are along +z -->
				<pose> 0 0 -0.055 0 0 0 </pose>
				<geometry>
					<cylinder>
						<radius>0.0025</radius>
						<length>0.11</length>
					</cylinder>
				</geometry>
				<material>
					<ambient>1. 0.25 0.5 1.</ambient>
					<diffuse>1. 0.25 0.5 1.</diffuse>
				</material>
			</visual>
			<visual name="right_front_shin_ball_vis">
				<pose>0 0 -0.11 0. 0. 0.</pose>
				<geometry>
					<sphere>
						<radius>0.01</radius>
					</sphere>
				</geometry>
				<material>
					<ambient>1. 0.25 0.5 1.</ambient>
					<diffuse>1. 0.25 0.5 1.</diffuse>
				</material>
			</visual>
			<collision name="right_front_shin_ball_vis">
				<pose>0 0 -0.11 0. 0. 0.</pose>
				<geometry>
					<sphere>
						<radius>0.01</radius>
					</sphere>
				</geometry>
			</collision>
		</link>
		<joint name="right_front_knee_pitch" type="revolute">
			<parent>right_front_hip</parent>
			<child>right_front_shin</child>
			<pose relative_to="right_front_hip">
                0 -0.01 -0.11 0 0 0
            </pose>
			<axis>
				<!-- axis is in child frame -->
				<xyz>0 1. 0</xyz>
				<limit>
					<lower>-3.1415</lower>
					<upper>0</upper>
					<effort>1.0</effort>
					<velocity>10</velocity>
				</limit>
				<dynamics>
					<damping>1.5e-2</damping>
				</dynamics>
				<initial_position>-1.57075</initial_position>
			</axis>
		</joint>
		<!-- Pelvis -->
		<link name="left_back_pelvis">
			<pose relative_to="body">
                -0.125 0 0 0 0 0
            </pose>
			<inertial>
				<pose>0 0 0 0 0 0</pose>
				<mass>0.0001</mass>
				<inertia>
					<ixx>3.3333333333333335e-11</ixx>
					<ixy>0</ixy>
					<ixz>0</ixz>
					<iyy>3.3333333333333335e-11</iyy>
					<iyz>0</iyz>
					<izz>5.000000000000001e-11</izz>
				</inertia>
			</inertial>
			<visual name="left_back_pelvis_rod_visual">
				<!-- Cylinders are along +z -->
				<pose> 0 0.025 0 1.57075 0 0 </pose>
				<geometry>
					<cylinder>
						<radius>0.005</radius>
						<length>0.05</length>
					</cylinder>
				</geometry>
				<material>
					<ambient>0.25 1.0 0.5 1.0</ambient>
					<diffuse>0.25 1.0 0.5 1.0</diffuse>
				</material>
			</visual>
			<visual name="left_back_pelvis_ball_visual">
				<pose>0 0.05 0 0 0 0 </pose>
				<geometry>
					<sphere>
						<radius>0.01</radius>
					</sphere>
				</geometry>
				<material>
					<ambient>0.25 1.0 0.5 1.0</ambient>
					<diffuse>0.25 1.0 0.5 1.0</diffuse>
				</material>
			</visual>
		</link>
		<joint name="left_back_body2pelvis" type="fixed">
			<parent>body</parent>
			<child>left_back_pelvis</child>
			<pose relative_to="body">
                -0.125 0 0 0 0 0
            </pose>
		</joint>
		<!-- hip abduction-->
		<link name="left_back_hip_inner">
			<pose relative_to="left_back_pelvis">
                0 0.05 0 0 0 0
            </pose>
			<inertial>
				<!-- Guessing the massive servos pull the COM to right between them -->
				<pose>-0.01 0.01 0 0 0 0</pose>
				<!-- approx standin inertia -->
				<mass>0.1</mass>
				<inertia>
					<ixx>9.895833333333333e-07</ixx>
					<ixy>0</ixy>
					<ixz>0</ixz>
					<iyy>9.895833333333333e-07</iyy>
					<iyz>0</iyz>
					<izz>3.125e-07</izz>
				</inertia>
				<mass>0.1</mass>
			</inertial>
			<visual name="left_back_inner_hip_rod_x_visual">
				<!-- Cylinders are along +z -->
				<pose> 0.01/2 0 0 0 1.57075 0 </pose>
				<geometry>
					<cylinder>
						<radius>0.0025</radius>
						<length>0.01</length>
					</cylinder>
				</geometry>
				<material>
					<ambient>0.25 1.0 0.5 1.0</ambient>
					<diffuse>0.25 1.0 0.5 1.0</diffuse>
				</material>
			</visual>
			<visual name="left_back_inner_hip_rod_y_visual">
				<!-- Cylinders are along +z -->
				<pose> 0.01 0.005 0 1.57075 0 0 </pose>
				<geometry>
					<cylinder>
						<radius>0.0025</radius>
						<length>0.01</length>
					</cylinder>
				</geometry>
				<material>
					<ambient>0.25 1.0 0.5 1.0</ambient>
					<diffuse>0.25 1.0 0.5 1.0</diffuse>
				</material>
			</visual>
			<visual name="left_back_inner_hip_ball_visual">
				<pose>0.01 0.01 0 0 0 0 </pose>
				<geometry>
					<sphere>
						<radius>0.01</radius>
					</sphere>
				</geometry>
				<material>
					<ambient>0.25 1.0 0.5 1.0</ambient>
					<diffuse>0.25 1.0 0.5 1.0</diffuse>
				</material>
			</visual>
			<visual name="left_back_inner_hip_box_visual">
				<pose>0.005 0.005 0 0 0 0</pose>
				<geometry>
					<box>
						<size>0.04 0.04 0.04</size>
					</box>
				</geometry>
				<material>
					<ambient>0.25 1.0 0.5 1.0</ambient>
					<diffuse>0.25 1.0 0.5 1.0</diffuse>
				</material>
			</visual>
		</link>
		<joint name="left_back_hip_roll" type="revolute">
			<parent>left_back_pelvis</parent>
			<child>left_back_hip_inner</child>
			<pose relative_to="left_back_pelvis">
                0 0.05 0. 0. 0. 0
            </pose>
			<axis>
				<xyz>1. 0. 0.</xyz>
				<limit>
					<lower>-1.57075</lower>
					<upper>1.57075</upper>
					<effort>1.0</effort>
					<velocity>10</velocity>
				</limit>
				<dynamics>
					<damping>1.5e-2</damping>
				</dynamics>
			</axis>
		</joint>
		<!-- hip-->
		<link name="left_back_hip">
			<!-- Goes straight down at base posture -->
			<pose relative_to="left_back_hip_inner">
                0.01 0.01 0 0 0 0
            </pose>
			<inertial>
				<pose>0 0 -0.055 0 0 0</pose>
				<mass>0.05</mass>
				<inertia>
					<ixx>5.049479166666667e-05</ixx>
					<ixy>0</ixy>
					<ixz>0</ixz>
					<iyy>5.049479166666667e-05</iyy>
					<iyz>0</iyz>
					<izz>1.5625e-07</izz>
				</inertia>
			</inertial>
			<visual name="left_back_hip_rod_visual">
				<!-- Cylinders are along +z -->
				<pose> 0 0 -0.055 0 0 0 </pose>
				<geometry>
					<cylinder>
						<radius>0.0025</radius>
						<length>0.11</length>
					</cylinder>
				</geometry>
				<material>
					<ambient>0.25 1.0 0.5 1.0</ambient>
					<diffuse>0.25 1.0 0.5 1.0</diffuse>
				</material>
			</visual>
			<visual name="left_back_hip_ball_vis">
				<pose>0 0 -0.11 0. 0. 0.</pose>
				<geometry>
					<sphere>
						<radius>0.01</radius>
					</sphere>
				</geometry>
				<material>
					<ambient>0.25 1.0 0.5 1.0</ambient>
					<diffuse>0.25 1.0 0.5 1.0</diffuse>
				</material>
			</visual>
			<collision name="left_back_hip_ball_vis">
				<pose>0 0 -0.11 0. 0. 0.</pose>
				<geometry>
					<sphere>
						<radius>0.01</radius>
					</sphere>
				</geometry>
			</collision>
		</link>
		<joint name="left_back_hip_pitch" type="revolute">
			<parent>left_back_hip_inner</parent>
			<child>left_back_hip</child>
			<pose relative_to="left_back_hip_inner">
                0.01 0.01 0 0 0 0
            </pose>
			<axis>
				<xyz>0. 1. 0.</xyz>
				<limit>
					<lower>-1.57075</lower>
					<upper>1.57075</upper>
					<effort>1.0</effort>
					<velocity>10</velocity>
				</limit>
				<dynamics>
					<damping>1.5e-2</damping>
				</dynamics>
			</axis>
		</joint>
		<!-- shin-->
		<link name="left_back_shin">
			<!-- Points straight down at angle=0 -->
			<pose relative_to="left_back_hip">
                0 0.01 -0.11 0 0 0
            </pose>
			<inertial>
				<pose>0 0 -0.055 0 0 0</pose>
				<mass>0.05</mass>
				<inertia>
					<ixx>5.049479166666667e-05</ixx>
					<ixy>0</ixy>
					<ixz>0</ixz>
					<iyy>5.049479166666667e-05</iyy>
					<iyz>0</iyz>
					<izz>1.5625e-07</izz>
				</inertia>
			</inertial>
			<visual name="left_back_hip_rod_visual">
				<!-- Cylinders are along +z -->
				<pose> 0 0 -0.055 0 0 0 </pose>
				<geometry>
					<cylinder>
						<radius>0.0025</radius>
						<length>0.11</length>
					</cylinder>
				</geometry>
				<material>
					<ambient>0.25 1.0 0.5 1.0</ambient>
					<diffuse>0.25 1.0 0.5 1.0</diffuse>
				</material>
			</visual>
			<visual name="left_back_shin_ball_vis">
				<pose>0 0 -0.11 0. 0. 0.</pose>
				<geometry>
					<sphere>
						<radius>0.01</radius>
					</sphere>
				</geometry>
				<material>
					<ambient>0.25 1.0 0.5 1.0</ambient>
					<diffuse>0.25 1.0 0.5 1.0</diffuse>
				</material>
			</visual>
			<collision name="left_back_shin_ball_vis">
				<pose>0 0 -0.11 0. 0. 0.</pose>
				<geometry>
					<sphere>
						<radius>0.01</radius>
					</sphere>
				</geometry>
			</collision>
		</link>
		<joint name="left_back_knee_pitch" type="revolute">
			<parent>left_back_hip</parent>
			<child>left_back_shin</child>
			<pose relative_to="left_back_hip">
                0 0.01 -0.11 0 0 0
            </pose>
			<axis>
				<!-- axis is in child frame -->
				<xyz>0 1. 0</xyz>
				<limit>
					<lower>-3.1415</lower>
					<upper>0</upper>
					<effort>1.0</effort>
					<velocity>10</velocity>
				</limit>
				<dynamics>
					<damping>1.5e-2</damping>
				</dynamics>
				<initial_position>-1.57075</initial_position>
			</axis>
		</joint>
		<!-- Pelvis -->
		<link name="right_back_pelvis">
			<pose relative_to="body">
                -0.125 0 0 0 0 0
            </pose>
			<inertial>
				<pose>0 0 0 0 0 0</pose>
				<mass>0.0001</mass>
				<inertia>
					<ixx>3.3333333333333335e-11</ixx>
					<ixy>0</ixy>
					<ixz>0</ixz>
					<iyy>3.3333333333333335e-11</iyy>
					<iyz>0</iyz>
					<izz>5.000000000000001e-11</izz>
				</inertia>
			</inertial>
			<visual name="right_back_pelvis_rod_visual">
				<!-- Cylinders are along +z -->
				<pose> 0 -0.025 0 1.57075 0 0 </pose>
				<geometry>
					<cylinder>
						<radius>0.005</radius>
						<length>0.05</length>
					</cylinder>
				</geometry>
				<material>
					<ambient>0.5 1.0 0.25 1.0</ambient>
					<diffuse>0.5 1.0 0.25 1.0</diffuse>
				</material>
			</visual>
			<visual name="right_back_pelvis_ball_visual">
				<pose>0 -0.05 0 0 0 0 </pose>
				<geometry>
					<sphere>
						<radius>0.01</radius>
					</sphere>
				</geometry>
				<material>
					<ambient>0.5 1.0 0.25 1.0</ambient>
					<diffuse>0.5 1.0 0.25 1.0</diffuse>
				</material>
			</visual>
		</link>
		<joint name="right_back_body2pelvis" type="fixed">
			<parent>body</parent>
			<child>right_back_pelvis</child>
			<pose relative_to="body">
                -0.125 0 0 0 0 0
            </pose>
		</joint>
		<!-- hip abduction-->
		<link name="right_back_hip_inner">
			<pose relative_to="right_back_pelvis">
                0 -0.05 0 0 0 0
            </pose>
			<inertial>
				<!-- Guessing the massive servos pull the COM to right between them -->
				<pose>-0.01 -0.01 0 0 0 0</pose>
				<!-- approx standin inertia -->
				<mass>0.1</mass>
				<inertia>
					<ixx>9.895833333333333e-07</ixx>
					<ixy>0</ixy>
					<ixz>0</ixz>
					<iyy>9.895833333333333e-07</iyy>
					<iyz>0</iyz>
					<izz>3.125e-07</izz>
				</inertia>
				<mass>0.1</mass>
			</inertial>
			<visual name="right_back_inner_hip_rod_x_visual">
				<!-- Cylinders are along +z -->
				<pose> 0.01/2 0 0 0 1.57075 0 </pose>
				<geometry>
					<cylinder>
						<radius>0.0025</radius>
						<length>0.01</length>
					</cylinder>
				</geometry>
				<material>
					<ambient>0.5 1.0 0.25 1.0</ambient>
					<diffuse>0.5 1.0 0.25 1.0</diffuse>
				</material>
			</visual>
			<visual name="right_back_inner_hip_rod_y_visual">
				<!-- Cylinders are along +z -->
				<pose> 0.01 -0.005 0 1.57075 0 0 </pose>
				<geometry>
					<cylinder>
						<radius>0.0025</radius>
						<length>0.01</length>
					</cylinder>
				</geometry>
				<material>
					<ambient>0.5 1.0 0.25 1.0</ambient>
					<diffuse>0.5 1.0 0.25 1.0</diffuse>
				</material>
			</visual>
			<visual name="right_back_inner_hip_ball_visual">
				<pose>0.01 -0.01 0 0 0 0 </pose>
				<geometry>
					<sphere>
						<radius>0.01</radius>
					</sphere>
				</geometry>
				<material>
					<ambient>0.5 1.0 0.25 1.0</ambient>
					<diffuse>0.5 1.0 0.25 1.0</diffuse>
				</material>
			</visual>
			<visual name="right_back_inner_hip_box_visual">
				<pose>0.005 -0.005 0 0 0 0</pose>
				<geometry>
					<box>
						<size>0.04 0.04 0.04</size>
					</box>
				</geometry>
				<material>
					<ambient>0.5 1.0 0.25 1.0</ambient>
					<diffuse>0.5 1.0 0.25 1.0</diffuse>
				</material>
			</visual>
		</link>
		<joint name="right_back_hip_roll" type="revolute">
			<parent>right_back_pelvis</parent>
			<child>right_back_hip_inner</child>
			<pose relative_to="right_back_pelvis">
                0 -0.05 0. 0. 0. 0
            </pose>
			<axis>
				<xyz>1. 0. 0.</xyz>
				<limit>
					<lower>-1.57075</lower>
					<upper>1.57075</upper>
					<effort>1.0</effort>
					<velocity>10</velocity>
				</limit>
				<dynamics>
					<damping>1.5e-2</damping>
				</dynamics>
			</axis>
		</joint>
		<!-- hip-->
		<link name="right_back_hip">
			<!-- Goes straight down at base posture -->
			<pose relative_to="right_back_hip_inner">
                0.01 -0.01 0 0 0 0
            </pose>
			<inertial>
				<pose>0 0 -0.055 0 0 0</pose>
				<mass>0.05</mass>
				<inertia>
					<ixx>5.049479166666667e-05</ixx>
					<ixy>0</ixy>
					<ixz>0</ixz>
					<iyy>5.049479166666667e-05</iyy>
					<iyz>0</iyz>
					<izz>1.5625e-07</izz>
				</inertia>
			</inertial>
			<visual name="right_back_hip_rod_visual">
				<!-- Cylinders are along +z -->
				<pose> 0 0 -0.055 0 0 0 </pose>
				<geometry>
					<cylinder>
						<radius>0.0025</radius>
						<length>0.11</length>
					</cylinder>
				</geometry>
				<material>
					<ambient>0.5 1.0 0.25 1.0</ambient>
					<diffuse>0.5 1.0 0.25 1.0</diffuse>
				</material>
			</visual>
			<visual name="right_back_hip_ball_vis">
				<pose>0 0 -0.11 0. 0. 0.</pose>
				<geometry>
					<sphere>
						<radius>0.01</radius>
					</sphere>
				</geometry>
				<material>
					<ambient>0.5 1.0 0.25 1.0</ambient>
					<diffuse>0.5 1.0 0.25 1.0</diffuse>
				</material>
			</visual>
			<collision name="right_back_hip_ball_vis">
				<pose>0 0 -0.11 0. 0. 0.</pose>
				<geometry>
					<sphere>
						<radius>0.01</radius>
					</sphere>
				</geometry>
			</collision>
		</link>
		<joint name="right_back_hip_pitch" type="revolute">
			<parent>right_back_hip_inner</parent>
			<child>right_back_hip</child>
			<pose relative_to="right_back_hip_inner">
                0.01 -0.01 0 0 0 0
            </pose>
			<axis>
				<xyz>0. 1. 0.</xyz>
				<limit>
					<lower>-1.57075</lower>
					<upper>1.57075</upper>
					<effort>1.0</effort>
					<velocity>10</velocity>
				</limit>
				<dynamics>
					<damping>1.5e-2</damping>
				</dynamics>
			</axis>
		</joint>
		<!-- shin-->
		<link name="right_back_shin">
			<!-- Points straight down at angle=0 -->
			<pose relative_to="right_back_hip">
                0 -0.01 -0.11 0 0 0
            </pose>
			<inertial>
				<pose>0 0 -0.055 0 0 0</pose>
				<mass>0.05</mass>
				<inertia>
					<ixx>5.049479166666667e-05</ixx>
					<ixy>0</ixy>
					<ixz>0</ixz>
					<iyy>5.049479166666667e-05</iyy>
					<iyz>0</iyz>
					<izz>1.5625e-07</izz>
				</inertia>
			</inertial>
			<visual name="right_back_hip_rod_visual">
				<!-- Cylinders are along +z -->
				<pose> 0 0 -0.055 0 0 0 </pose>
				<geometry>
					<cylinder>
						<radius>0.0025</radius>
						<length>0.11</length>
					</cylinder>
				</geometry>
				<material>
					<ambient>0.5 1.0 0.25 1.0</ambient>
					<diffuse>0.5 1.0 0.25 1.0</diffuse>
				</material>
			</visual>
			<visual name="right_back_shin_ball_vis">
				<pose>0 0 -0.11 0. 0. 0.</pose>
				<geometry>
					<sphere>
						<radius>0.01</radius>
					</sphere>
				</geometry>
				<material>
					<ambient>0.5 1.0 0.25 1.0</ambient>
					<diffuse>0.5 1.0 0.25 1.0</diffuse>
				</material>
			</visual>
			<collision name="right_back_shin_ball_vis">
				<pose>0 0 -0.11 0. 0. 0.</pose>
				<geometry>
					<sphere>
						<radius>0.01</radius>
					</sphere>
				</geometry>
			</collision>
		</link>
		<joint name="right_back_knee_pitch" type="revolute">
			<parent>right_back_hip</parent>
			<child>right_back_shin</child>
			<pose relative_to="right_back_hip">
                0 -0.01 -0.11 0 0 0
            </pose>
			<axis>
				<!-- axis is in child frame -->
				<xyz>0 1. 0</xyz>
				<limit>
					<lower>-3.1415</lower>
					<upper>0</upper>
					<effort>1.0</effort>
					<velocity>10</velocity>
				</limit>
				<dynamics>
					<damping>1.5e-2</damping>
				</dynamics>
				<initial_position>-1.57075</initial_position>
			</axis>
		</joint>
		--&gt;
    
	</model>
</sdf>
